Workbook
Name ArbMode: Listes!$B$359:$B$365
Name Autom: Listes!$B$410:$B$411
Name BULLET: 'APPENDIX B-2 (FE - USEC&GC)'!$N$13:$N$22
Name BULLET: 'APPENDIX F-1 ISC-US'!$N$13:$N$18
Name BULLET: 'APPENDIX F-2 ISC-USWC'!$N$13:$N$18
Name BULLET: 'APPENDIX B-1 (FE - USWC)'!$N$13:$N$20
Name Charges: Listes!$A$3:$A$230
Name Container: Listes!$B$245:$B$254
Name CST: Listes!$B$434:$B$440
Name CURRENCY: Listes!$B$483:$B$618
Name DAYS: Listes!$B$449:$B$450
Name DDTARIFF: Listes!$B$454:$B$457
Name DDTARIFFUS: Listes!$B$461:$B$463
Name DDTARIFFUSE: Listes!$B$466:$B$467
Name DDTARIFFUSI: Listes!$B$461:$B$463
Name droppull: Listes!$B$292:$B$293
Name EQTYPE: Listes!$B$471:$B$474
Name Equip: Listes!$B$374:$B$397
Name Exceptions: Listes!$H$3:$H$231
Name EXPIMP: Listes!$B$444:$B$445
Name GRIPSS: Listes!$B$368:$B$371
Name GRIPSS_EQ: Listes!$B$415:$B$430
Name Mode: Listes!$B$296:$B$344
Name MQCType: Listes!$B$400:$B$402
Name OLE_LINK1: 'Boiler Plate'!$A$377
Name OOG: Listes!$B$355:$B$356
Name OPREEFER: Listes!$B$478:$B$479
Name Reefer: Listes!$B$258:$B$264
Name SDD: Listes!$B$234:$B$237
Name shipper: Cover!$B$7
Name ShipperCert: Listes!$B$405:$B$406
Name ShipperOwn: Listes!$B$351:$B$352
Name Type_note2: Listes!$B$267:$B$289
Name YesNo: Listes!$B$347:$B$348

Sheet Boiler Plate
A1: =CONCATENATE("AMENDMENT ",Cover!B2," TO SERVICE CONTRACT ",Cover!B1) -> AMENDMENT 58 TO SERVICE CONTRACT 25-3117
A3: =CONCATENATE(" This Amendment to the Service Contract (the “Amendment”) is made as of the date of filing of the Amendment with the Federal Maritime Commission (the “Effective Date”), by and between CMA CGM S.A. (hereinafter referred to as “Carrier”) and ",IF(Cover!B7="","__________",Cover!B7)," (hereinafter referred to as “Merchant”).") -> This Amendment to the Service Contract (the “Amendment”) is made as of the date of filing of the Amendment with the Federal Maritime Commission (the “Effective Date”), by and between CMA CGM S.A. (hereinafter referred to as “Carrier”) and LOGISTIQUE PRIME FREIGHT INC (hereinafter referred to as “Merchant”).
A5: WHEREAS, Carrier and Merchant hereby agree to amend the Contract as defined herein.
A7: NOW THEREFORE, intending to be legally bound Carrier and Merchant hereby agree that this Amendment shall amend the Contract as follows:
A9: Pursuant to the attached Excel document and/or the following revisions:
A11: Section | B11: Heading
A12: Term | B12: Appendix
A13: 6 | B13: B1,B2: Rates
A23: BOTH PARTIES HEREBY AGREE THAT THE REMAINING TERMS AND CONDITIONS OF THE CONTRACT SHALL NOT BE AMENDED BY THIS WRITING AND SHALL REMAIN IN FULL FORCE AND EFFECT FOR THE DURATION OF THE TERM.
A25: IN WITNESS WHEREOF, THE PARTIES HERETO HAVE EXECUTED THIS AMENDMENT TO THE SERVICE CONTRACT, WHICH SHALL BECOME EFFECTIVE AS OF THE DATE OF FILING WITH THE FEDERAL MARITIME COMMISSION.
A27: The individual signing this Amendment on behalf of the Merchant represents and warrants that he or she is empowered and duly authorized to bind the Merchant to this Amendment according to its terms.
A31: ______________________________ | B31: ______________________________
A32: Signature | B32: Signature
A34: Date_________11/12/2025_________ | B34: Date__________________
A35: Charles A. Gender | B35: =IF(Cover!B9="","Name: ________________________",Cover!B9) -> Neil Sabharwal
A36: Sr. Director, Bids and Contracting | B36: =IF(Cover!B10="","Title: _________________________",Cover!B10) -> Managing Director
A37: CMA CGM (America) LLC
A38: As Agents for: | B38: For and on Behalf of:
A39: CMA CGM S.A. | B39: =IF(Cover!B7="","(Merchant)",Cover!B7) -> LOGISTIQUE PRIME FREIGHT INC
A40: CMA CGM S.A.
A42: Service Contract Number: | B42: =Cover!B1 -> 25-3117
A44: Essential Terms (“ET”) Number: | B44: CMDU 037
A48: =CONCATENATE("This Service Contract (“Contract”) will become effective (the “Effective Date”) upon date signed by both parties as required by 46 §CFR 530.8 and will expire on ",IF(Cover!B6="","__________",TEXT(Cover!B6,"mmmmmmmmm dd, yyyy")),".", " In no event shall the Effective Date be earlier than thirty (30) days prior to the filing of the Contract with the Federal Maritime Commission (“FMC”).") -> This Service Contract (“Contract”) will become effective (the “Effective Date”) upon date signed by both parties as required by 46 §CFR 530.8 and will expire on December 31, 2025. In no event shall the Effective Date be earlier than thirty (30) days prior to the filing of the Contract with the Federal Maritime Commission (“FMC”).
A50: =CONCATENATE("This Contract is made by and between CMA CGM S.A., a French company having its registered office at Boulevard Jacques Saadé, 4 Quai d'Arenc, 13235 Marseille CEDEX 02, France (hereinafter referred to as “Carrier”) and ",IF(Cover!B7="","__________",Cover!B7),", (hereinafter referred to as “Merchant”) whereby the parties mutually agree to bind themselves to the terms and conditions set forth herein.") -> This Contract is made by and between CMA CGM S.A., a French company having its registered office at Boulevard Jacques Saadé, 4 Quai d'Arenc, 13235 Marseille CEDEX 02, France (hereinafter referred to as “Carrier”) and LOGISTIQUE PRIME FREIGHT INC, (hereinafter referred to as “Merchant”) whereby the parties mutually agree to bind themselves to the terms and conditions set forth herein.
A52: =CONCATENATE("Pursuant to FMC Regulation 46 C.F.R. §530.6, by execution of this Contract, Merchant certifies its status and that of all of its affiliates authorized to use this Contract as: (1) ",IF(Cover!B19="YES","__X__","_____")," Owner of the Cargo ('Beneficial Cargo Owner' or 'BCO'), (2) ",IF(Cover!B21="YES","__X__","_____")," Non-Vessel Operating Common Carrier (NVOCC), or (3) ",IF(Cover!B20="YES","__X__","_____"), " Shipper's Association",".") -> Pursuant to FMC Regulation 46 C.F.R. §530.6, by execution of this Contract, Merchant certifies its status and that of all of its affiliates authorized to use this Contract as: (1) _____ Owner of the Cargo ('Beneficial Cargo Owner' or 'BCO'), (2) __X__ Non-Vessel Operating Common Carrier (NVOCC), or (3) _____ Shipper's Association.
A54: =IF(Cover!B21="YES",CONCATENATE("For all Merchants certifying their status as a NVOCC, it is further certified that Merchant is a duly licensed and bonded NVOCC having a published tariff and surety bond number ",IF(Cover!B22="","__________",Cover!B22),", dated ",IF(Cover!B23="","__________",TEXT(Cover!B23,"mmmmmmmmm dd, yyyy")),", issued by ",IF(Cover!B24="","__________",Cover!B24)," on ",IF(Cover!F23="",IF(Cover!B23="","__________",TEXT(Cover!B23,"mmmmmmmmm dd, yyyy")),TEXT(Cover!F23,"mmmmmmmmm dd, yyyy")),", which has been filed with the FMC, that an appropriate tariff or tariffs have been filed with the FMC, and that copies of tariff pages have been provided to Carrier."),"") -> For all Merchants certifying their status as a NVOCC, it is further certified that Merchant is a duly licensed and bonded NVOCC having a published tariff and surety bond number KMS52005, dated October 16, 2024, issued by SOUTHWEST MARINE AND GENERAL INSURANCE COMPANY on October 16, 2024, which has been filed with the FMC, that an appropriate tariff or tariffs have been filed with the FMC, and that copies of tariff pages have been provided to Carrier.
A56: As legally required, Carrier’s Bill of Lading, Merchant’s statement of containers shipped under this Contract, written communications issued by Carrier regarding such statement, and force majeure correspondence and notices, shall constitute the records supporting performance under this Contract, and shall be maintained by Carrier’s designated agent in the United States of America at the following address:
A58: CMA CGM (America) LLC 1 CMA CGM Way, Norfolk, Virginia 23502 Phone: (757) 961-2100
A60: In witness whereof, the parties hereby agree to ratify any electronic signatures and be bound by the terms and conditions of this Contract by signature of their duly authorized representatives, set forth below.
A62: The individual signing this Contract on behalf of the Merchant represents and warrants that he or she is empowered and duly authorized to bind the Merchant to this Contract according to its terms.
A66: ______________________________ | B66: ______________________________
A67: Signature | B67: Signature
A69: Date ___________1/31/2025______________ | B69: Date ___________2/7/2025______________
A70: Charles A. Gender | B70: =IF(Cover!B9="","Contact:",Cover!B9) -> Neil Sabharwal
A71: Sr. Director, Bids and Contracting | B71: =IF(Cover!B10="","Title:",Cover!B10) -> Managing Director
A73: For and on behalf of: | B73: For and on behalf of:
A74: CMA CGM (America) LLC
A75: As agents for:
A76: CMA CGM S.A. | B76: =IF(Cover!B7="","",Cover!B7) -> LOGISTIQUE PRIME FREIGHT INC
A77: 1 CMA CGM Way | B77: =IF(Cover!B11="","",Cover!B11) -> 4 PLACE DU COMMERCE SUITE 230, QUEBEC
...

Sheet Cover
A1: Service Contract #: | B1: 25-3117
A2: Amendment #: | B2: 58
A3: Effective Date of Amendment: | B3: 45974
A4: Term 4 MQC: | B4: =MQC!E8 -> 150 | C4: TEUS
A5: Term 8 Contract Effective Date: | B5: 45703
A6: Term 8 Contract Expiration Date: | B6: 46022
A7: Term 2 Merchant Name: | B7: LOGISTIQUE PRIME FREIGHT INC
A8: Partner Code: | B8: 0004563721
A9: 41 Contact Person: | B9: Neil Sabharwal
A10: Title: | B10: Managing Director
A11: Address: | B11: 4 PLACE DU COMMERCE SUITE 230, QUEBEC
B12: Montreal, Canada. H3E1J4.
A14: Phone: | B14: 5146555430
A15: Fax:
A16: Email: | B16: neil@primefreight.com
A17: SVI:
A18: Term 10 Merchant Certification: | B18: You must indicate one of the following as (YES)
A19: Owner of the Cargo (BCO)
A20: Shippers Association
A21: NVOCC | B21: YES
A22: If NVOCC, provide Bond Number: | B22: KMS52005
A23: If NVOCC, provide Bond date | B23: 45581
A24: If NVOCC provide the name of the Bonding Company | B24: SOUTHWEST MARINE AND GENERAL INSURANCE COMPANY
A25: If NVOCC resides in the USA, provide FMC License Number: Or If NVOCC resides outside the USA, provide FMC Organization Number: | B25: 034170
A26: If NVOCC, Shipper Certifies to Carrier that they are an Ocean Transportation Intermediary (OTI) performing NVOCC Services. OTI License and Bond are on file with the FMC.
A27: Term 100 Tariff(s) of General Applicability: | B27: CMDU 020, 100, 102 , 043 , 029
A29: Term 101 Free Time Exceptions:
A30: A - Demurrage / B - Detention | B30: Per Tariff(s) unless specified in Appendix "Term 101 FREE TIME Exceptions"
A31: CMA-CGM Sales Representative: | B31: DU Shuang
B32: cda.sdu@usa.cma-cgm.com
A33: Table of Contents
A34: CMDU#044 | B34: A-1 | C34: OUTBOUND FAR EAST (USWC-ASIA) | E34: =A34 -> CMDU#044
A35: CMDU#044 | B35: A-2 | C35: OUTBOUND FAR EAST (USEC&USGC-ASIA) | E35: =A35 -> CMDU#044
A36: CMDU#043 B1 | B36: B-1 | C36: INBOUND FAR EAST (ASIA-USWC) | E36: =A36 -> CMDU#043 B1
A37: CMDU#043 B2 | B37: B-2 | C37: INBOUND FAR EAST (ASIA-USEC & USGC) | E37: =A37 -> CMDU#043 B2
A38: CMDU#028 | B38: C-1 | C38: OUTBOUND (USA-MEDITERRANEAN) | E38: =A38 -> CMDU#028
A39: CMDU#028 | B39: C-2 | C39: OUTBOUND (USA-ARABIAN GULF & RED SEA) | E39: =A39 -> CMDU#028
A40: CMDU#028 | B40: C-3 | C40: OUTBOUND (USWC-ARABIAN GULF) | E40: =A40 -> CMDU#028
A41: CMDU#028 | B41: C-5 | C41: OUTBOUND (USA-E & W AFRICA) | E41: =A41 -> CMDU#028
A42: CMDU#029 D1 | B42: D-1 | C42: INBOUND (MEDITERRANEAN-USA EC & GC) (AMERIGO) | E42: =A42 -> CMDU#029 D1
...

Sheet MQC
B2: MQC | C2: Appendix | E2: (TEUS)
C3: ALL | E3: 150
C8: Total | E8: =SUM(E3:E6) -> 150
A9: 41

Sheet APPENDIX B-1  (FE - USWC)
A1: Service Contract: | C1: =Cover!B1 -> 25-3117
A2: TERM 6
A3: Amendment Number: | C3: =Cover!B2 -> 58
A4: Merchant Name: | C4: =Cover!B7 -> LOGISTIQUE PRIME FREIGHT INC
A5: Appendix: | C5: B-1
A6: Trade Service: | C6: INBOUND FAR EAST (ASIA-USWC)
A7: TARIFF applicability | C7: CMDU#043 B1
A9: 41 | B9: INB
A11: COMMODITY INDEX
A12: - Unless otherwise indicated, excludes temperature controlled cargo, hazardous cargo, cargo requiring special handling and/or equipment, overweight containers.
A13: FAK/Bullets | B13: Description | J13: Named Account | L13: Partner Code | N13: ALL
A14: FAK PSW | B14: FAK | N14: =IF($A14>0,$A14,"") -> FAK PSW
A15: FAK PNW | B15: FAK | N15: =IF($A15>0,$A15,"") -> FAK PNW
A16: FAK HAWAII | B16: FAK | N16: =IF($A16>0,$A16,"") -> FAK HAWAII
N17: =IF($A17>0,$A17,"")
N18: =IF($A18>0,$A18,"")
N19: =IF($A19>0,$A19,"")
N20: =IF($A20>0,$A20,"")
A21: Port Group Codes
A22: Port Group Codes | B22: Description
A23: BP TW | B23: KAOHSIUNG,TAIPEI
A24: BP VAN | B24: YANTIAN,XIAMEN,NINGBO,SHANGHAI,HONG KONG,SHEKOU
A25: LAX-LGB | B25: LOS ANGELES,LONG BEACH
A26: BP SEA | B26: SHANGHAI,YANTIAN,XIAMEN,NINGBO,SHEKOU,HONG KONG
A27: BP TIW | B27: YANTIAN,SHANGHAI,NINGBO
A28: BP FUJI | B28: TOKYO, NAGOYA, KOBE
A29: BP LAX | B29: NANSHA,YANTIAN,XIAMEN,SHANGHAI,NINGBO,QINGDAO,TIANJINXINGANG
A30: BP OAK | B30: YANTIAN,SHEKOU,SHANGHAI,NINGBO,QINGDAO
A31: SE ASIA BP PSW | B31: PORT KLANG,SINGAPORE,LAEM CHABANG,VUNG TAU,HAIPHONG
A32: BP PRR | B32: SHANGHAI,QINGDAO,TIANJINXINGANG
A33: NCPRC BP OAK | B33: SHANGHAI, NINGBO, QINGDAO
... A36: SPRC BP OAK | B36: YANTIAN, SHEKOU
A41: RATES CONDITIONS
A42: Rates in USD unless otherwise specified. Surcharges listed per line item are exceptions to Note 2 applicability.
A43: For Place of Receipt indicate origin of cargo
A44: For Place of Intermodal Delivery indicate point and state. Mode: PORT=CY, RAIL=R (RAMP), MOTOR=M , RAIL/MOTOR=RM , BARGE=B, RAIL/BARGE=RB (RAMP), MOTOR/BARGE=BM
A45: FAK/ BULLETS | B45: Place of Receipt | C45: POL | D45: POD | E45: Place of Delivery | F45: MODE | G45: SDD (Origin; Dest) | H45: Curr | I45: D20 | J45: D40 | K45: H40 | L45: H45 | X45: Effective date | Y45: Expiration Date | Z45: Note | AA45: IPI Construction
A47: FAK PSW | C47: NCPRC BP LAX | D47: LAX-LGB | F47: CY/CY | G47: N/N | H47: USD | I47: 1785 | J47: 2100 | K47: 2100 | L47: 2660 | Z47: 1,2,4 | AA47: E
A48: FAK PSW | C48: NCPRC BP OAK | D48: OAKLAND, CA | F48: CY/CY | G48: N/N | H48: USD | I48: 1785 | J48: 2100 | K48: 2100 | L48: 2660 | Z48: 1,2,4 | AA48: E
A49: FAK PSW | C49: NCPRC BP LAX | D49: LAX-LGB | E49: CHICAGO, IL | F49: CY/R | G49: N/N | H49: USD | I49: 3870 | J49: 4550 | K49: 4550 | L49: 5760 | Z49: 1,2,4 | AA49: E
...

Sheet APPENDIX B-2  (FE - USEC&GC)
A1: Service Contract: | C1: =Cover!B1 -> 25-3117
A2: TERM 6
A3: Amendment Number: | C3: =Cover!B2 -> 58
A4: Merchant Name: | C4: =Cover!B7 -> LOGISTIQUE PRIME FREIGHT INC
A5: Appendix: | C5: B-2
A6: Trade Service: | C6: INBOUND FAR EAST (ASIA-USEC & USGC)
A7: TARIFF applicability | C7: CMDU#043 B2
A9: 41 | B9: INB
A11: COMMODITY INDEX
A12: - Unless otherwise indicated, excludes temperature controlled cargo, hazardous cargo, cargo requiring special handling and/or equipment, overweight containers.
A13: FAK/Bullets | B13: Description | J13: Named Account | L13: Partner Code | N13: ALL
A14: FAK BAL | B14: FAK | N14: =IF($A14>0,$A14,"") -> FAK BAL
A15: FAK EC | B15: FAK | N15: =IF($A15>0,$A15,"") -> FAK EC
A16: FAK GCFL | B16: FAK | N16: =IF($A16>0,$A16,"") -> FAK GCFL
A17: FAK MIA | B17: FAK | N17: =IF($A17>0,$A17,"") -> FAK MIA
A18: FAK BOS | B18: FAK
N19: =IF($A19>0,$A19,"")
N20: =IF($A20>0,$A20,"")
N21: =IF($A21>0,$A21,"")
N22: =IF($A22>0,$A22,"")
A23: Port Group Codes
A24: Port Group Codes | B24: Description
A25: BP BAL | B25: XIAMEN,HONG KONG,YANTIAN
A26: SE ASIA BP GCFL | B26: VUNG TAU,SINGAPORE
A27: GULF | B27: HOUSTON,MOBILE,NEW ORLEANS
A28: BP JAPAN | B28: NAGOYA, SHIMIZU, TOKYO, KOBE, YOKOHAMA, OSAKA, HIROSHIMA, MOJI, HAKATA/FUKUOKA
A29: NCPRC BP EC | B29: SHANGHAI,NINGBO,QINGDAO
A30: SE ASIA BP EC | B30: VUNG TAU,PORT KLANG,SINGAPORE,HAIPHONG
A31: BP MIA | B31: PORT KLANG,HAIPHONG,YANTIAN,NINGBO,SHANGHAI,XIAMEN,SHEKOU
A32: BP GCFL | B32: NINGBO,SHANGHAI,XIAMEN,YANTIAN,SHEKOU
A33: SPRC BP EC | B33: YANTIAN,SHEKOU,XIAMEN,HONG KONG,YANGPU
A37: RATES CONDITIONS
A38: Rates in USD unless otherwise specified. Surcharges listed per line item are exceptions to Note 2 applicability.
A39: For Place of Receipt indicate origin of cargo
A40: For Place of Intermodal Delivery indicate point and state. Mode: PORT=CY, RAIL=R (RAMP), MOTOR=M , RAIL/MOTOR=RM , BARGE=B, RAIL/BARGE=RB (RAMP), MOTOR/BARGE=BM
A41: FAK/ BULLETS | B41: Place of Receipt | C41: POL | D41: POD | E41: Place of Delivery | F41: MODE | G41: SDD (Origin; Dest) | H41: Curr | I41: D20 | J41: D40 | K41: H40 | L41: H45 | X41: Effective date | Y41: Expiration Date | Z41: Note | AA41: IPI Construction
A43: FAK BAL | C43: BP BAL | D43: BALTIMORE, MD | F43: CY/CY | G43: N/N | H43: USD | I43: 2080 | J43: 2600 | K43: 2600 | L43: 3290 | Z43: 1,2,4 | AA43: E
A44: FAK BAL | C44: KAOHSIUNG | D44: BALTIMORE, MD | F44: CY/CY | G44: N/N | H44: USD | I44: 2080 | J44: 2600 | K44: 2600 | L44: 3290 | Z44: 1,2,4 | AA44: E
A45: FAK BAL | C45: LAEM CHABANG | D45: BALTIMORE, MD | F45: CY/CY | G45: N/N | H45: USD | I45: 2160 | J45: 2700 | K45: 2700 | L45: 3420 | Z45: 1,2,4 | AA45: E
A46: FAK BAL | C46: VUNG TAU | D46: BALTIMORE, MD | F46: CY/CY | G46: N/N | H46: USD | I46: 2160 | J46: 2700 | K46: 2700 | L46: 3420 | Z46: 1,2,4 | AA46: E
...

Sheet APPENDIX F-1 ISC-US
A1: Service Contract: | C1: =Cover!B1 -> 25-3117
A2: TERM 6
A3: Amendment Number: | C3: =Cover!B2 -> 58
A4: Merchant Name: | C4: =Cover!B7 -> LOGISTIQUE PRIME FREIGHT INC
A5: Appendix: | C5: F-1
A6: Trade Service: | C6: INBOUND (INDIAN SUB. CONTINENT-USA EC) (INDAMEX)
A7: TARIFF applicability | C7: CMDU#029 F1
A9: 43 | B9: INB
A11: COMMODITY INDEX
A12: - Unless otherwise indicated, excludes temperature controlled cargo, hazardous cargo, cargo requiring special handling and/or equipment, overweight containers.
A13: FAK/Bullets | B13: Description | J13: Named Account | L13: Partner Code | N13: ALL
A14: FAK BD | B14: FAK | N14: =IF($A14>0,$A14,"") -> FAK BD
N15: =IF($A15>0,$A15,"")
N16: =IF($A16>0,$A16,"")
N17: =IF($A17>0,$A17,"")
N18: =IF($A18>0,$A18,"")
A19: Port Group Codes
A20: Port Group Codes | B20: Description
A26: RATES CONDITIONS
A27: Rates in USD unless otherwise specified. Surcharges listed per line item are exceptions to Note 2 applicability.
A28: For Place of Receipt indicate origin of cargo
A29: For Place of Intermodal Delivery indicate point and state. Mode: PORT=CY, RAIL=R (RAMP), MOTOR=M , RAIL/MOTOR=RM , BARGE=B, RAIL/BARGE=RB (RAMP), MOTOR/BARGE=BM
A30: FAK/ BULLETS | B30: Place of Receipt | C30: POL | D30: POD | E30: Place of Delivery | F30: MODE | G30: SDD (Origin; Dest) | H30: Curr | I30: D20 | J30: D40 | K30: H40 | L30: H45 | M30: PSS | N30: PSS2 | O30: PSS3 | P30: BAF | X30: Effective date | Y30: Expiration Date | Z30: Note | AA30: IPI Construction
M31: Appl/ Not Appl | N31: Appl/ Not Appl | O31: Appl/ Not Appl | P31: Appl/ Not Appl
A32: FAK BD | C32: CHITTAGONG | D32: CHARLESTON, SC | F32: CY/CY | G32: N/N | H32: USD | I32: 3060 | J32: 3400 | K32: 3400 | L32: 4305 | M32: Not Applicable | N32: Not Applicable | O32: Not Applicable | P32: Not Applicable | Z32: 1,2,3,4 | AA32: B
A33: FAK BD | C33: CHITTAGONG | D33: NORFOLK, VA | F33: CY/CY | G33: N/N | H33: USD | I33: 3060 | J33: 3400 | K33: 3400 | L33: 4305 | M33: Not Applicable | N33: Not Applicable | O33: Not Applicable | P33: Not Applicable | Z33: 1,2,3,4 | AA33: B
A34: FAK BD | C34: CHITTAGONG | D34: SAVANNAH, GA | F34: CY/CY | G34: N/N | H34: USD | I34: 3060 | J34: 3400 | K34: 3400 | L34: 4305 | M34: Not Applicable | N34: Not Applicable | O34: Not Applicable | P34: Not Applicable | Z34: 1,2,3,4 | AA34: B
A35: FAK BD | C35: CHITTAGONG | D35: NEW YORK, NY | F35: CY/CY | G35: N/N | H35: USD | I35: 3060 | J35: 3400 | K35: 3400 | L35: 4305 | M35: Not Applicable | N35: Not Applicable | O35: Not Applicable | P35: Not Applicable | Z35: 1,2,3,4 | AA35: B
A36: FAK BD | C36: CHITTAGONG | D36: BALTIMORE, MD | F36: CY/CY | G36: N/N | H36: USD | I36: 4905 | J36: 5450 | K36: 5450 | L36: 6900 | M36: Not Applicable | N36: Not Applicable | O36: Not Applicable | P36: Not Applicable | Z36: 1,2,3,4 | AA36: B
A37: FAK BD | C37: CHITTAGONG | D37: SAVANNAH, GA | E37: ATLANTA, GA | F37: CY/R | G37: N/N | H37: USD | I37: 4050 | J37: 4500 | K37: 4500 | L37: 5695 | M37: Not Applicable | N37: Not Applicable | O37: Not Applicable | P37: Not Applicable | Z37: 1,2,3,4 | AA37: B
A38: FAK BD | C38: CHITTAGONG | D38: SAVANNAH, GA | E38: CHARLOTTE, NC | F38: CY/R | G38: N/N | H38: USD | I38: 4500 | J38: 5000 | K38: 5000 | L38: 6330 | M38: Not Applicable | N38: Not Applicable | O38: Not Applicable | P38: Not Applicable | Z38: 1,2,3,4 | AA38: B
A39: FAK BD | C39: CHITTAGONG | D39: SAVANNAH, GA | E39: CHATSWORTH, GA | F39: CY/R | G39: N/N | H39: USD | I39: 4140 | J39: 4600 | K39: 4600 | L39: 5825 | M39: Not Applicable | N39: Not Applicable | O39: Not Applicable | P39: Not Applicable | Z39: 1,2,3,4 | AA39: B
A40: FAK BD | C40: CHITTAGONG | D40: CHARLESTON, SC | E40: GREER, SC | F40: CY/R | G40: N/N | H40: USD | I40: 4590 | J40: 5100 | K40: 5100 | L40: 6455 | M40: Not Applicable | N40: Not Applicable | O40: Not Applicable | P40: Not Applicable | Z40: 1,2,3,4 | AA40: B
A41: FAK BD | C41: CHITTAGONG | D41: CHARLESTON, SC | E41: DILLON, SC | F41: CY/R | G41: N/N | H41: USD | I41: 4590 | J41: 5100 | K41: 5100 | L41: 6455 | M41: Not Applicable | N41: Not Applicable | O41: Not Applicable | P41: Not Applicable | Z41: 1,2,3,4 | AA41: B
A42: FAK BD | C42: CHITTAGONG | D42: NEW YORK, NY | E42: CHICAGO, IL | F42: CY/R | G42: N/N | H42: USD | I42: 4860 | J42: 5400 | K42: 5400 | L42: 6835 | M42: Not Applicable | N42: Not Applicable | O42: Not Applicable | P42: Not Applicable | Z42: 1,2,3,4 | AA42: B
A43: FAK BD | C43: CHITTAGONG | D43: NORFOLK, VA | E43: CHICAGO, IL | F43: CY/R | G43: N/N | H43: USD | I43: 4860 | J43: 5400 | K43: 5400 | L43: 6835 | M43: Not Applicable | N43: Not Applicable | O43: Not Applicable | P43: Not Applicable | Z43: 1,2,3,4 | AA43: B
A44: FAK BD | C44: CHITTAGONG | D44: NEW YORK, NY | E44: CINCINNATI, OH | F44: CY/R | G44: N/N | H44: USD | I44: 4680 | J44: 5200 | K44: 5200 | L44: 6585 | M44: Not Applicable | N44: Not Applicable | O44: Not Applicable | P44: Not Applicable | Z44: 1,2,3,4 | AA44: B
A45: FAK BD | C45: CHITTAGONG | D45: NORFOLK, VA | E45: CINCINNATI, OH | F45: CY/R | G45: N/N | H45: USD | I45: 4680 | J45: 5200 | K45: 5200 | L45: 6585 | M45: Not Applicable | N45: Not Applicable | O45: Not Applicable | P45: Not Applicable | Z45: 1,2,3,4 | AA45: B
A46: FAK BD | C46: CHITTAGONG | D46: NEW YORK, NY | E46: CLEVELAND, OH | F46: CY/R | G46: N/N | H46: USD | I46: 4680 | J46: 5200 | K46: 5200 | L46: 6585 | M46: Not Applicable | N46: Not Applicable | O46: Not Applicable | P46: Not Applicable | Z46: 1,2,3,4 | AA46: B
A47: FAK BD | C47: CHITTAGONG | D47: NORFOLK, VA | E47: CLEVELAND, OH | F47: CY/R | G47: N/N | H47: USD | I47: 4680 | J47: 5200 | K47: 5200 | L47: 6585 | M47: Not Applicable | N47: Not Applicable | O47: Not Applicable | P47: Not Applicable | Z47: 1,2,3,4 | AA47: B
...

Sheet APPENDIX F-2 ISC-USWC
A1: Service Contract: | C1: =Cover!B1 -> 25-3117
A2: TERM 6
A3: Amendment Number: | C3: =Cover!B2 -> 58
A4: Merchant Name: | C4: =Cover!B7 -> LOGISTIQUE PRIME FREIGHT INC
A5: Appendix: | C5: F-2
A6: Trade Service: | C6: INBOUND (INDIAN SUB. CONTINENT-USA WC ) (TPX)
A7: TARIFF applicability | C7: CMDU#029 F2
A9: 43 | B9: INB
A11: COMMODITY INDEX
A12: - Unless otherwise indicated, excludes temperature controlled cargo, hazardous cargo, cargo requiring special handling and/or equipment, overweight containers.
A13: FAK/Bullets | B13: Description | J13: Named Account | L13: Partner Code | N13: ALL
A14: FAK | B14: FAK | N14: =IF($A14>0,$A14,"") -> FAK
N15: =IF($A15>0,$A15,"")
N16: =IF($A16>0,$A16,"")
N17: =IF($A17>0,$A17,"")
N18: =IF($A18>0,$A18,"")
A19: Port Group Codes
A20: Port Group Codes | B20: Description
A21: LAX-LGB | B21: LOS ANGELES, LONG BEACH
A26: RATES CONDITIONS
A27: Rates in USD unless otherwise specified. Surcharges listed per line item are exceptions to Note 2 applicability.
A28: For Place of Receipt indicate origin of cargo
A29: For Place of Intermodal Delivery indicate point and state. Mode: PORT=CY, RAIL=R (RAMP), MOTOR=M , RAIL/MOTOR=RM , BARGE=B, RAIL/BARGE=RB (RAMP), MOTOR/BARGE=BM
A30: FAK/ BULLETS | B30: Place of Receipt | C30: POL | D30: POD | E30: Place of Delivery | F30: MODE | G30: SDD (Origin; Dest) | H30: Curr | I30: D20 | J30: D40 | K30: H40 | L30: H45 | M30: OTHC | X30: Effective date | Y30: Expiration Date | Z30: Note | AA30: IPI Construction
M31: Appl/ Not Appl
A32: FAK | C32: KOLKATA(CALCUTTA) | D32: LAX-LGB | F32: CY/CY | G32: N/N | H32: USD | I32: 1600 | J32: 2000 | K32: 2000 | L32: 2530 | Z32: 1,2,4 | AA32: E
A33: FAK | C33: CHENNAI | D33: LAX-LGB | F33: CY/CY | G33: N/N | H33: USD | I33: 1520 | J33: 1900 | K33: 1900 | L33: 2405 | Z33: 1,2,4 | AA33: E
A34: FAK | C34: CHITTAGONG | D34: LAX-LGB | F34: CY/CY | G34: N/N | H34: USD | I34: 1760 | J34: 2200 | K34: 2200 | L34: 2785 | M34: Not Applicable | Z34: 1,2,4 | AA34: E
A35: FAK | C35: COCHIN | D35: LAX-LGB | F35: CY/CY | G35: N/N | H35: USD | I35: 1730 | J35: 2160 | K35: 2160 | L35: 2735 | Z35: 1,2,4 | AA35: E
A36: FAK | C36: COLOMBO | D36: LAX-LGB | F36: CY/CY | G36: N/N | H36: USD | I36: 1680 | J36: 2100 | K36: 2100 | L36: 2660 | Z36: 1,2,4 | AA36: E
A37: FAK | B37: DHAKA | C37: CHITTAGONG | D37: LAX-LGB | F37: R/CY | G37: N/N | H37: USD | I37: 2000 | J37: 2500 | K37: 2500 | L37: 3165 | M37: Not Applicable | Z37: 1,2,4 | AA37: E
A38: FAK | C38: HALDIA | D38: LAX-LGB | F38: CY/CY | G38: N/N | H38: USD | I38: 1680 | J38: 2100 | K38: 2100 | L38: 2660 | Z38: 1,2,4 | AA38: E
A39: FAK | C39: HAZIRA | D39: LAX-LGB | F39: CY/CY | G39: N/N | H39: USD | I39: 1520 | J39: 1900 | K39: 1900 | L39: 2405 | Z39: 1,2,4 | AA39: E
A40: FAK | C40: KARACHI | D40: LAX-LGB | F40: CY/CY | G40: N/N | H40: USD | I40: 1520 | J40: 1900 | K40: 1900 | L40: 2405 | Z40: 1,2,4 | AA40: E
A41: FAK | C41: KRISHNAPATNAM | D41: LAX-LGB | F41: CY/CY | G41: N/N | H41: USD | I41: 1680 | J41: 2100 | K41: 2100 | L41: 2660 | Z41: 1,2,4 | AA41: E
A42: FAK | C42: MANGALORE | D42: LAX-LGB | F42: CY/CY | G42: N/N | H42: USD | I42: 1600 | J42: 2000 | K42: 2000 | L42: 2530 | Z42: 1,2,4 | AA42: E
A43: FAK | C43: MUNDRA | D43: LAX-LGB | F43: CY/CY | G43: N/N | H43: USD | I43: 1520 | J43: 1900 | K43: 1900 | L43: 2405 | Z43: 1,2,4 | AA43: E
A44: FAK | C44: NHAVA SHEVA | D44: LAX-LGB | F44: CY/CY | G44: N/N | H44: USD | I44: 1520 | J44: 1900 | K44: 1900 | L44: 2405 | Z44: 1,2,4 | AA44: E
A45: FAK | C45: PIPAVAV | D45: LAX-LGB | F45: CY/CY | G45: N/N | H45: USD | I45: 1520 | J45: 1900 | K45: 1900 | L45: 2405 | Z45: 1,2,4 | AA45: E
A46: FAK | C46: TUTICORIN | D46: LAX-LGB | F46: CY/CY | G46: N/N | H46: USD | I46: 1520 | J46: 1900 | K46: 1900 | L46: 2405 | Z46: 1,2,4 | AA46: E
...

Sheet Affiliates
A1: Service Contract: | B1: =Cover!B1 -> 25-3117 | I1: 21
A2: TERM 3
A3: Amendment Number: | B3: =Cover!B2 -> 58
A4: Merchant Name: | B4: =Cover!B7 -> LOGISTIQUE PRIME FREIGHT INC
A5: Appendix: | B5: =Cover!C62 -> Affiliates
A6: 41
A7: LIST OF AFFILIATES / SHIPPER ASSOCIATION MEMBERS
A8: Signatory certifies that they have an ownership interest in all named affiliates. | G8: For NVOCC Affiliates
A9: Partner Code | B9: Name | C9: Street Address | D9: City | E9: State & Zip Code | F9: Country | G9: NVOCC Bond Number
A10: 0006023501 | B10: UNIQUE LOGISTICS INTERNATIONAL (NYC), , LOS ANGELES | C10: 10810 PAINTER AVENUE SANTA FE | D10: LOS ANGELES | E10: SPRINGS, CA 90670 | F10: US

Sheet Listes
A1: Template INBOUND OUTBOUND | B1: V41
A2: Charges | D2: Prepaid/collect | E2: Text / Calc | F2: Level of calc | H2: Exception Charges
A3: 10% CO2 Reduction | B3: 10% CO2 Reduction | C3: ENV06 | D3: Prepaid | E3: Calc | F3: Cargo | H3: 10% CO2 Reduction
A4: 25% CO2 Reduction | B4: 25% CO2 Reduction | C4: ENV02 | D4: Prepaid | E4: Calc | F4: Cargo | H4: 25% CO2 Reduction
A5: 50% CO2 Reduction | B5: 50% CO2 Reduction | C5: ENV10 | D5: Prepaid | E5: Calc | F5: Cargo | H5: 50% CO2 Reduction
A6: 83% CO2 Reduction | B6: 83% CO2 Reduction | C6: ENV04 | D6: Prepaid | E6: Calc | F6: Cargo | H6: 83% CO2 Reduction
A7: ACS Export | B7: Alameda Corridor Surcharge export | C7: CAR12 | D7: Prepaid | E7: Calc | F7: Cargo | H7: ACS Export
A8: ACS Import | B8: Alameda Corridor Surcharge import | C8: CAR10 | D8: Prepaid | E8: Calc | F8: Cargo | H8: ACS Import
A9: Alcohol Surcharge, Oncarriage | B9: On Carriage, Alcohol Surcharge | C9: CAR64 | D9: Collect | E9: Calc | F9: Cargo | H9: Alcohol Surcharge, Oncarriage
A10: Alcohol Surcharge, Precarriage | B10: Pre Carriage, Alcohol Surcharge | C10: CAR14 | D10: Prepaid | E10: Calc | F10: Cargo | H10: Alcohol Surcharge, Precarriage
A11: Atmosphere Control | B11: Atmosphere Control Transport Unit Charge | C11: FRT12 | D11: Prepaid | E11: Calc | F11: Cargo | H11: Atmosphere Control
A12: BAF | B12: Bunker Adjustment Factor | C12: BAF03 | D12: Prepaid | E12: Calc | F12: Cargo | H12: BAF
A13: Bar Lock Security Device | B13: Bar Lock Security Device | C13: SEA07 | D13: Prepaid | E13: Calc | F13: Cargo | H13: Bar Lock Security Device
A14: Benin Freight Tax | B14: Benin Freight Tax | C14: TAX08 | D14: Prepaid | E14: Calc | F14: Cargo | H14: Benin Freight Tax
... A123: Nigerian Freight Tax | B123: Nigerian Freight Tax | C123: TAX09 | D123: Prepaid | E123: Calc | F123: Cargo | H123: Nigerian Freight Tax
A124: NMSA | B124: National Maritime Safety Surcharge | C124: PNG01 | E124: Calc | F124: Cargo | H124: NMSA
A125: O/C EIFS | B125: On-Carriage Emergency Inland Fuel Surcharge | C125: CAR97 | D125: Prepaid | E125: Calc | F125: Cargo | H125: O/C EIFS
A126: O/C Exp Rail | B126: On-Carriage Expedited Rail | C126: CAR84 | D126: Collect | E126: Calc | F126: Cargo | H126: O/C Exp Rail
A127: O/C Haulage | B127: On-Carriage Haulage | C127: CAR50 | D127: Collect | E127: Calc | F127: Cargo | H127: O/C Haulage
A128: O/C Pre Pull VAS CAR PRIME | B128: On-Carriage Pre-Pull VAS Car Prime | C128: CAR61 | D128: Collect | E128: Calc | F128: Cargo | H128: O/C Pre Pull VAS CAR PRIME
A129: O/C Sealing GPS | B129: On Carriage Sealing GPS additional | C129: CAR98 | D129: Collect | E129: Calc | F129: Cargo | H129: O/C Sealing GPS
A130: OC Multi Stop | B130: On Carriage Multistop | C130: CAR52 | D130: Collect | E130: Calc | F130: Cargo | H130: OC Multistop
A131: Off Dock | B131: Off Dock Surcharge | C131: TAX28 | D131: Collect | E131: Calc | F131: Cargo | H131: Off Dock
A132: Oncarriage Barge | B132: OnCarriage Barge - Congestion | C132: CAR54 | D132: Collect | E132: Calc | F132: Cargo | H132: OnCarriage Barge
A133: Oncarriage Congestion | B133: OnCarriage Congestion | C133: CAR81 | D133: Collect | E133: Calc | F133: Cargo | H133: OnCarriage Congestion
A134: On-Carriage Emergency Surcharge | B134: On-Carriage Emergency Intermodal Surcharge | C134: CAR96 | D134: Prepaid | E134: Calc | F134: Cargo | H134: OnCarriage Emergency Intermodal
A135: Oncarriage Hazardous Charge | B135: Inland Hazardous Charge Oncarriage | C135: CAR65 | D135: Collect | E135: Calc | F135: Cargo | H135: Oncarriage Hazardous Charge
A136: Oncarriage Ramp | B136: On-Carriage to Ramp | C136: CAR55 | D136: Collect | E136: Calc | F136: Cargo | H136: Oncarriage Ramp
... A229: X-Ray, Carrier | B229: Scanning by Customs, incl other examinations, carrier | C229: CUS70 | D229: Prepaid | E229: Calc | F229: Cargo | H229: X-Ray, Carrier
A230: GRI | B230: General Rate Increase | C230: GRI general | D230: Prepaid | E230: Calc | F230: Cargo
B233: SDD
B234: N/N
B235: Y/N
B236: Y/Y
B237: N/Y
B243: DRY
B244: Container
B245: Appl/ Not Appl
B246: Per B/L
B247: Per Cargo
...

Sheet SOF BR
A1: Signature on File / Bond Rider
